Workbook

Sheet One Page
A1: KPIS Gerais
A2: Etapa | B2: KPI | C2: Baseline (2025) | D2: Target | E2: Abr | F2: Mai | G2: Jun
A3: Atração & Recrutamento | B3: Capacity do time de TA [Total Vagas] | C3: =5*7 -> 35 | D3: Á definir | R3: =TODAY() -> 46169
B4: Time to fill | C4: - | D4: Á definir
B5: Time to Hire | C5: - | D5: Á definir
B6: Quality of hire [%] | C6: 71 | D6: 0.8
B7: CSAT Etapas TA [unid] | C7: 4 | D7: Á definir
B8: NPS do Candidato | C8: 8.6 | D8: Á definir
B9: Custo por Contratação | C9: Á definir | D9: Á definir
A10: Carreira & reconhecimento | B10: eNPS da Liderança | C10: 62 | D10: 71
B11: Taxa de Adoção (MAU: Monthly Active Users) [%] | C11: N/A | D11: Á definir
B12: NPS Team Guide | C12: NA | D12: Á definir
A13: HRBP | B13: HRBP/HC [Taxa] | C13: 1 | 121 | D13: 1 | 250
E15: Legenda | G15: Concluído | Z15: Legenda | AB15: Público Alvo
G16: Até Mai'25 | AB16: Impacto Indireto
G17: Após Mai'25
A19: Projetos Priorizados | H19: Etapa | P19: Métricas | W19: Time | Z19: Público Impactado | AE19: Agendas
A20: Jornada do Neowner | B20: Etapa Jornada do Neowner | C20: Projeto | D20: Descrição do Projeto | E20: Interface | F20: Tema | G20: Impacto | H20: Etapa | I20: Desenvolvimento: Data Final | J20: Testes People | L20: Go-to-Market: New Wave 1 | N20: Go-to-Market: New Wave 2 | P20: Métrica | Q20: Descrição Métrica | R20: Baseline | S20: Target | T20: Mai | U20: Jun | V20: Jul | W20: Owner | X20: Co Owner | Y20: HRBP | Z20: Líder | AA20: BP | AB20: TA | AC20: C&TD | AD20: TR | AE20: Daily | AF20: Weekly | AG20: Weekly
A21: Atração | B21: 1.Hunting | C21: Abertura de Vagas | D21: Otimização do processo de abertura de vagas via Slack, com foco na redução da carga operacional para Lideres, TA e HRBP. Implementação de automação integrando Lever, LG e Slack, garantindo a integridade dos dados críticos e a agilidade do fluxo | E21: Slack | F21: Abertura de Vaga | G21: Self-service operacional: Descentralização com foco na experiência do gestor. | H21: Desenvolvimento | I21: 46185 | J21: =I21+3 -> 46188 | K21: =J21+11 -> 46199 | L21: =K21+3 -> 46202 | M21: =L21+11 -> 46213 | N21: =M21+3 -> 46216 | O21: =N21+11 -> 46227 | P21: Lead Time | Q21: Tempo no Processo de abertura da vaga pelo Gestor no Slack | R21: À definir | S21: À definir | T21: - | U21: - | V21: - | W21: Fernanda Nobre Granjo Lelli Almeida | X21: Rafael Nunes da Silva Baraccat | Y21: Matheus Henrique Rocha | AE21: N/A | AF21: Segunda | AG21: 11h
P22: CSAT | Q22: Satisfação do Gestor com o novo processo de de abertura da Vaga no Slack | R22: 3,6 | S22: 4.3
P23: Redução de Campos de Preechimento [Qnt] | Q23: Redução dos Campos de Preechimento Lever > Slack | R23: 27 | S23: 13
E24: People Platform | F24: Criação de Posição | G24: Integridade de Dados: Conformidade e eliminação de erros via automação do processo. | H24: Desenvolvimento | I24: 46185 | J24: =I24+3 -> 46188 | K24: =J24+11 -> 46199 | L24: =K24+3 -> 46202 | M24: =L24+11 -> 46213 | N24: =M24+3 -> 46216 | O24: =N24+11 -> 46227 | P24: Lead Time [h/mês] | Q24: Tempo no Processo de criação da posição na LG pelo HRBP | R24: 2 | S24: 0 | T24: - | U24: - | V24: - | W24: Fernanda Nobre Granjo Lelli Almeida | X24: Rafael Nunes da Silva Baraccat | Y24: Matheus Henrique Rocha | AE24: N/A | AF24: Segunda | AG24: 11h
A25: Atração | B25: 1.Hunting | C25: POC: Hunting Assistant Linkedin | D25: O LinkedIn Hiring Assistant e a Pesquisa Assistida automatizam o hunting ao criar vagas e buscar candidatos via IA, economizando mais de 4h por função. A ferramenta reduz em 62% a análise de perfis desnecessários, focando na pré-seleção cirúrgica de talentos qualificados. Através de linguagem natural, o agente identifica candidatos passivos com o melhor fit técnico e cultural para a posição. | E25: Linkedin | F25: Hunting Assistant | G25: Eficiência em Sourcing: Maximização da conversão do funil e redução do Time-to-Fill. | H25: Teste Interno | I25: 46122 | J25: =I25+3 -> 46125 | K25: =J25+90 -> 46215 | P25: Taxa de Conversão [%] | Q25: Leads convertidos por Hiring Assistant / Total de Leads convertidos | R25: 64 | S25: 70 | T25: - | U25: - | V25: - | W25: Nicole Haviaras Dos Santos | X25: Andreza Cardoso Pimenta | AE25: N/A | AF25: N/A | AG25: N/A
P26: Taxa de Contratação [%] | Q26: Contratados por Hiring Assistant / Total de Contratados | R26: 3,4 | S26: Á definir | T26: - | U26: - | V26: -
P27: Usabilidade do linkedin hiring assistant | Q27: Usabilidade do linkedin hiring assistant pelos recrutadores (por mês por recrutador) | R27: 10 | S27: 8.5 | T27: - | U27: - | V27: -
A28: Atração | B28: 2.Shortlist | C28: Farol de Vagas | D28: O Farol de Vagas automatiza o envio de insights e status para gestores via Slack e People Platform. Ele apresenta visualmente o funil de recrutamento e o volume de candidatos por etapa, eliminando o envio manual de relatórios e otimizando drasticamente a rotina do time de TA | E28: People Platform | F28: Farol de Vagas | G28: Visibility & Ownership: Gestão transparente do progresso do recrutamento dando autonomia para o gestor. | H28: Desenvolvimento | I28: 46218 | J28: =I28+3 -> 46221 | K28: =J28+11 -> 46232 | L28: =K28+3 -> 46235 | M28: =L28+11 -> 46246 | P28: Taxa de Adoção [%] | Q28: % de Líderes que usam a nova ferramenta | R28: N/A | S28: 80 | T28: - | U28: - | V28: - | W28: Fernanda Nobre Granjo Lelli Almeida | X28: Rafael Nunes da Silva Baraccat | Y28: Gustavo Zaluski Camila Erika Arita | AE28: N/A | AF28: Segunda | AG28: 11h
P29: CSAT | Q29: Satisfação do Gestor com a ferramenta | R29: 3,6 | S29: 4.3 | T29: - | U29: - | V29: -
A30: Atração | B30: 3.Entrevista | C30: Parecer de Entrevista | D30: O Parecer de Entrevista utiliza IA para guiar o gestor de forma intuitiva, sugerindo perguntas estratégicas e gerando um score de desempenho ao final da conversa. Além de otimizar a condução da entrevista, a ferramenta oferece insights precisos para que o gestor preencha o parecer final com mais facilidade e assertividade. | E30: Slack | F30: Automação Parecer de entrevista | G30: Padronização de Seleção: Geração de score imparcial para entrevista e candidato avaliado | H30: Desenvolvimento | I30: 46185 | J30: =I30+3 -> 46188 | K30: =J30+18 -> 46206 | L30: =K30+3 -> 46209 | M30: =L30+30 -> 46239 | N30: =M30+3 -> 46242 | O30: =N30+11 -> 46253 | P30: Score Candidato [%] | Q30: Mede a qualidade do candidato (recomendações dos entrevistadores, consenso entre etapas, scores de competências 1-5) | R30: N/A | S30: À definir | T30: - | U30: - | V30: - | W30: Martha Lorena Silva Souza | X30: Andreza Cardoso Pimenta | Y30: Ligia Mayumi Hasimoto Shimizu | AE30: N/A | AF30: N/A | AG30: N/A
P31: Efetividade por entrevistador [%] | Q31: pipeline_quality_score médio por avaliador, para identificar onde o preenchimento de pareceres está mais fraco | R31: N/A | S31: Á definir
A32: Atração | B32: 3.Entrevista | C32: POC: Entrevistas com IA | D32: As Ferramentas de Entrevista com IA potencializam a pré-seleção ao analisar perfis com alta velocidade e precisão. O sistema gera automaticamente um score de aderência entre o candidato e a job description, garantindo que apenas os talentos mais qualificados avancem no processo. | E32: Lever | F32: POC: Tako | G32: Aceleração de Funil: Redução de latência nas etapas críticas de avaliação de candidatos. | H32: Teste Interno | I32: 46195 | J32: =I32+3 -> 46198 | K32: =J32+11 -> 46209 | L32: =K32+3 -> 46212 | M32: =L32+11 -> 46223 | N32: =M32+3 -> 46226 | O32: =N32+11 -> 46237 | P32: Taxa de Conversão Screening > Stage 2[%] | Q32: Taxa de Conversão Screening > Stage 2 (IA x Humano) | R32: 51,3 | S32: Á definir | T32: - | U32: - | V32: - | W32: Martha Lorena Silva Souza | X32: Andreza Cardoso Pimenta | Y32: Ligia Mayumi Hasimoto Shimizu | AE32: N/A | AF32: Sexta | AG32: 16h
P33: Taxa de Precisão [%] | Q33: Volume de candidatos Stage 2 que chegaram ao final do processo | R33: 27% | S33: 35¨% | T33: - | U33: - | V33: -
P34: Tempo Médio de Permanência na Etapa de Screening [horas] | Q34: Tempo Médio de Permanência na Etapa de Screening | R34: 151,2 | S34: Á definir | T34: - | U34: - | V34: -
P35: Taxa de contratação de pessoas diversas [%] | Q35: Contratados com recorte de diversidade (Mulher ou Preta/Parda ou PCD)/Total de Contratados | R35: 65 | S35: Á definir | T35: - | U35: - | V35: -
A36: Atração | B36: 3.Entrevista | E36: Lever | F36: POC: DigAI | G36: Aceleração de Funil: Redução de latência nas etapas críticas de avaliação de candidatos. | H36: Teste Interno | I36: 46171 | J36: =I36+3 -> 46174 | K36: =J36+11 -> 46185 | L36: =K36+3 -> 46188 | M36: =L36+11 -> 46199 | N36: =M36+3 -> 46202 | O36: =N36+11 -> 46213 | P36: Taxa de Conversão [%] | Q36: Taxa de conversão Triagem > Entrevista c/ Gestor (IA x Humano) | R36: 51,3 | S36: Á definir | T36: - | U36: - | V36: - | W36: Martha Lorena Silva Souza | X36: Andreza Cardoso Pimenta | Y36: Ligia Mayumi Hasimoto Shimizu | AE36: N/A | AF36: Sexta | AG36: 16h
P37: Taxa de Precisão [%] | Q37: Volume de candidatos Stage 2 que chegaram ao final do processo | R37: 27% | S37: 35¨% | T37: - | U37: - | V37: -
P38: Tempo Médio de Permanência na Etapa de Entrevista [horas] | Q38: Tempo Médio de Permanência na Etapa de Entrevista | R38: 151,2 | S38: Á definir | T38: - | U38: - | V38: -
P39: Taxa de contratação de pessoas diversas [%] | Q39: Contratados com recorte de diversidade (Mulher ou Preta/Parda ou PCD)/Total de Contratados | R39: 65 | S39: Á definir | T39: - | U39: - | V39: -
A40: Atração | B40: 3.Entrevista | C40: Automação de Agendas de Entrevistas | D40: O Agendador Inteligente elimina conflitos de horários ao identificar automaticamente os melhores intervalos para entrevistas entre gestores e candidatos. Com reserva direta e notificações instantâneas, a ferramenta garante agilidade ao processo e libera o time de Talent Acquisition da carga operacional de agendamentos manuais. | E40: Google Calendar e Slack | F40: Automação Agendas (Esteira) | G40: Excelência Operacional em TA: Redução de horas operacionais em agendamento de entrevista via automação da logística. | H40: Go Live (Onda 1) | I40: 46168 | J40: =I40+1 -> 46169 | K40: =J40+11 -> 46180 | L40: =K40+3 -> 46183 | M40: =L40+20 -> 46203 | P40: Lead Time [h/mês] | Q40: Tempo no agendamento de candidatos pela recrutadora | R40: 140 | S40: 0 | T40: - | U40: - | V40: - | W40: Fernanda Nobre Granjo Lelli Almeida | X40: Amanda Komuta | Y40: Amanda Pimentel Coimbra | AE40: N/A | AF40: Terça | AG40: 11h
A41: Atração | B41: 3.Entrevista | E41: Google Calendar e Slack | F41: Automação Agendas (Sem Esteira) | G41: Excelência Operacional em TA: Redução de horas operacionais em agendamento de entrevista via automação da logística. | H41: Desenvolvimento | I41: 46188 | J41: =I41+3 -> 46191 | K41: =J41+11 -> 46202 | L41: =K41+3 -> 46205 | M41: =L41+11 -> 46216 | P41: Lead Time [h/mês] | Q41: Tempo no agendamento de candidatos pela recrutadora | R41: 140 | S41: 0 | T41: - | U41: - | V41: - | W41: Fernanda Nobre Granjo Lelli Almeida | X41: Rafael Nunes da Silva Baraccat | Y41: Amanda Pimentel Coimbra | AE41: N/A | AF41: Segunda | AG41: 11h
A42: Recrutamento | B42: 5.Offer | C42: Simulação de Offer | D42: O Gerador de Propostas Inteligente automatiza a criação de offers com base em dados internos, como pretensão salarial, equidade entre pares e tabelas de cargos. O sistema acelera o envio da proposta final e conta com um fluxo de governança que notifica os times de TA e TR sobre casos outliers, garantindo agilidade e segurança orçamentária. | E42: People Platform | F42: Simulador de Offer 2.0 | G42: Previsibilidade Financeira: Agilidade na composição de propostas com automação de processos críticos | H42: Desenvolvimento | I42: 46168 | J42: =I42+1 -> 46169 | K42: =J42+16 -> 46185 | L42: =K42+30 -> 46215 | M42: =L42+11 -> 46226 | P42: Lead Time [h/mês] | Q42: Tempo no processo da Offer | R42: 80 | S42: 30 | T42: - | U42: - | V42: - | W42: Sabrina Mendes | X42: Andressa Vitoria Lopes de Oliveira | Y42: Matheus Henrique Rocha | AE42: N/A | AF42: Quarta | AG42: 14h
...

Sheet Weekly
A1: Weekly PATH | G1: Ago | I1: Set | M1: Out | R1: Nov | V1: Dez | Y1: Jan | AB1: Fev | AE1: Fev | AF1: Mar | AI1: Abr | AL1: Mai
A2: Frente | B2: Task | C2: Owner | D2: Time | E2: Status | F2: Esforço | G2: S3 | H2: S4 | I2: S1 | J2: S2 | K2: S3 | L2: S4 | M2: S1 | N2: S2 | O2: S3 | P2: S4 | Q2: S5 | R2: S1 | S2: S2 | T2: S3 | U2: S4 | V2: S1 | W2: S2 | X2: S3 | Y2: S2 | Z2: S3 | AA2: S4 | AB2: S1 | AC2: S2 | AD2: S3 | AE2: S4 | AF2: S1 | AG2: S2 | AH2: S3 | AI2: S1 | AJ2: S2 | AK2: S4 | AL2: S1 | AM2: S2
A3: API People | B3: Integração API People <> People Allocation | C3: Escobar | E3: Done | F3: Baixo | I3: x | J3: x | K3: x | L3: x
A4: API People | B4: Evolução API People e próximos passos | C4: Icaro | E4: Done | F4: Alto | G4: x
A5: API People | B5: Estrágia API People <> Sistemas | C5: Icaro | E5: Done | F5: Médio | H5: x
A6: API People | B6: Integração API People <> Github | C6: Icaro | E6: Done | F6: Alto | I6: x
A7: API People | B7: Integração API People <> AD | C7: Icaro | E7: Done | F7: Médio | I7: x
A8: API People | B8: Integração API People <> Jumpcloud | C8: Icaro | E8: Done | F8: Médio | I8: x
A9: API People | B9: Integração API People <> Service Now | C9: Icaro | E9: Done | F9: Baixo | J9: x | K9: x
A10: API QR | B10: Mapemento dados QR | C10: Deza | E10: Done | F10: Médio | L10: x
A11: API QR | B11: Camis <> Team Guide | C11: Deza | E11: Done | F11: Médio | L11: x
A12: API QR | B12: Desenvolvimento API QR Pesquisa | C12: Icaro | E12: Done | F12: Alto | K12: x | L12: x | M12: x
A13: TA | B13: Agendamento de entrevista: Tech e Crédito | C13: Amanda Komuta | E13: Done | F13: Médio | AB13: x | AC13: x | AD13: x | AE13: x | AF13: x | AG13: x | AH13: x | AI13: x
A14: AuditData | B14: Cadastrar Especialidade | C14: Ca | E14: Done | F14: Médio | I14: x | K14: x
A15: AuditData | B15: Comunicação Atualização Diária | C15: Thi | E15: Done | F15: Alto | K15: x | M15: x
A16: APP Neon | B16: APP Neon: View CPF | C16: Icaro | E16: Done | F16: Alto | K16: x | L16: x | N16: x
A17: AuditData | B17: Alinhamento TR sobre (Empresas, Relatório Ferias e relatório P4P) | C17: Deza | E17: Done | F17: Baixo | H17: x
A18: AuditData | B18: Atualização Quinzenal | C18: Thi | E18: Done | F18: Baixo | G18: x | J18: x
A19: AuditData | B19: Atualização Mensal (Lembrete KT e Avalição GT) | C19: Thi | E19: Done | F19: Baixo | I19: x
A20: Estrutura Funcional | B20: Canal PAS | C20: Ca | E20: Done | F20: Médio | K20: x
A21: AuditData | B21: SSOT e Position Management diária | C21: Thi | E21: Done | F21: Médio | J21: x | K21: x
A22: AuditData | B22: Atualização Quinzenal | C22: Thi | E22: Done | F22: Baixo | K22: x
A23: Estrutura Funcional | B23: Estrágia e próximos passos | C23: Deza | E23: Done | F23: Médio | K23: x | L23: x
A24: AuditData | B24: Duplicação UO | C24: Deza | E24: Done | F24: Baixo
A25: AutomaTIME | B25: Fechamento Mensal | C25: Deza | E25: Done | F25: Baixo | I25: x
A26: Estrutura Funcional | B26: Abrir novo workspace_neon | C26: Deza | E26: Done | F26: Médio | L26: x
A27: KPI Admissão | B27: Validação Propósta técnica Lever <> Lever | C27: Ca | E27: Done | F27: Médio | O27: x
A28: KPI Admissão | B28: Apresentação steakholders (Bre, Kell, Fer Lellis etc) | C28: Ca | E28: Done | F28: Médio | N28: x
A29: KPI Admissão | B29: Target horas projeto Admissão | C29: Ca | E29: Done | F29: Alto | G29: x | H29: x
A30: KPI Admissão | B30: Diagnóstico Processos As Is | C30: Ca | E30: Done | F30: Médio | H30: x
A31: KPI Admissão | B31: Diagnóstico Processos To be | C31: Ca | E31: Done | F31: Médio | K31: x | L31: x
A32: KPI Admissão | B32: Diagnóstico Tecnico | C32: Ca | E32: Done | F32: Médio | K32: x | L32: x
A33: Conexão Neon | B33: Semana Presencial | C33: Deza | E33: Done | F33: Baixo | I33: x
A34: Estratégia PATH | B34: Neogciação + homologação ( TeamGuide) | C34: Andreza Cardoso Pimenta | E34: Done | F34: Baixo | U34: x | V34: x | W34: x | X34: x | Y34: x | Z34: x | AA34: x | AB34: x | AC34: x
A35: Estratégia System | B35: V2 Material Estratégia | C35: Deza | E35: Done | F35: Médio | M35: x
A36: Estratégia System | B36: People Forúm | C36: Deza | E36: Done | F36: Alto | N36: x
A37: Estratégia System | B37: Mensal PAS | C37: Deza | E37: Done | F37: Médio | N37: x
A38: KPI Orçamento IA | B38: PMO DEV Assistente | C38: Ca | E38: Done | F38: Médio | G38: x | H38: x | I38: x | K38: x | L38: x | M38: x | Q38: x | R38: x
A39: KPI AutomaTIME | B39: Alinhamento com os owners | C39: Deza | E39: Done | F39: Baixo | H39: x
A40: KPI AutomaTIME | B40: Comunicações e Agendas | C40: Deza | E40: Done | F40: Médio | G40: x
...

Sheet POC
B2: Cronograma Dez'25 | H2: Cronograma Jan'26
B3: Seg | C3: Ter | D3: Qua | E3: Qui | F3: Sex | H3: Seg | I3: Ter | J3: Qua | K3: Qui | L3: Sex
B4: 1 | C4: =B4+1 -> 2 | D4: =C4+1 -> 3 | E4: =D4+1 -> 4 | F4: =E4+1 -> 5 | H4: 5 | I4: =H4+1 -> 6 | J4: =I4+1 -> 7 | K4: =J4+1 -> 8 | L4: =K4+1 -> 9
B5: =F4+3 -> 8 | C5: =B5+1 -> 9 | D5: =C5+1 -> 10 | E5: =D5+1 -> 11 | F5: =E5+1 -> 12 | H5: =L4+3 -> 12 | I5: =H5+1 -> 13 | J5: =I5+1 -> 14 | K5: =J5+1 -> 15 | L5: =K5+1 -> 16
B6: =F5+3 -> 15 | C6: =B6+1 -> 16 | D6: =C6+1 -> 17 | E6: =D6+1 -> 18 | F6: =E6+1 -> 19 | H6: =L5+3 -> 19 | I6: =H6+1 -> 20 | J6: =I6+1 -> 21 | K6: =J6+1 -> 22 | L6: =K6+1 -> 23
B7: =F6+3 -> 22 | C7: =B7+1 -> 23 | D7: =C7+1 -> 24 | E7: =D7+1 -> 25 | F7: =E7+1 -> 26 | H7: =L6+3 -> 26 | I7: =H7+1 -> 27 | J7: =I7+1 -> 28 | K7: =J7+1 -> 29 | L7: =K7+1 -> 30
B8: =F7+3 -> 29 | C8: =B8+1 -> 30 | D8: =C8+1 -> 31
N10: Pesquisa & Skills | P10: Carreira & LMS
C11: pré requisitos: definições must have + nice to have | M11: POC | N11: Dez'25 | O11: Jan'26 | P11: Dez'25 | Q11: Jan'26
C12: liberação de acessos | M12: Implantação | N12: Jan'26 | O12: Fev'26 | P12: Fev'26 | Q12: Mar'26
C13: go live POC & pré requisitos (must have + nice to have) | M13: Go Live | N13: Fev'26 | O13: Mar'26 | P13: Abr'26 | Q13: Mai'26
C14: AMA TeamGuide
C15: resultado aderência ferramenta (KPI's POC)
C16: debriefing entre áreas especialistas + HRBPs
C17: debriefing final steakholders
C18: diagnóstico final + pedidos de customizações

Sheet Backlog System
A1: Backlog de PAS no TRELLO
A2: Tema | B2: Task | C2: Responsável | D2: Status | E2: SLA
A3: Relatório P4P | B3: Customização do relatório por system | C3: Thi | D3: Done | E3: 45931
A4: Correção unidade org | B4: Revisão unidade organizacional LG | C4: Ca | D4: Done | E4: 45931
A5: Integração | B5: Integração Data Lake <> POST QR | C5: Pesquisa | D5: Done | E5: 45931
A6: Integração | B6: Integração Data Lake <> POST QR | C6: Carina | D6: Done | E6: 45962
A7: Data Lake | B7: CSV Orçamento | C7: Thi | D7: Done | E7: H1'2025
A8: Data Lake | B8: Histórico Sociedade | C8: Thi | D8: Done | E8: H1'2025
A9: Data Lake | B9: API Colaboradores | C9: Icaro | D9: Done | E9: H1'2025
A10: Data Lake | B10: API Desligados | C10: Icaro | D10: Done | E10: H1'2025
A11: Data Lake | B11: Tabela Salarial | C11: Icaro | D11: Done | E11: H1'2025
A12: Data Lake | B12: Produto SSOT | C12: Icaro | D12: Done | E12: H1'2025
A13: Data Lake | B13: Produto SSOT Drive | C13: Thi | D13: Done | E13: H1'2025
A14: Data Lake | B14: API Hierarquia | C14: Icaro | D14: Done | E14: H1'2025
A15: Data Lake | B15: API Movimentações | C15: Icaro | D15: Done | E15: H1'2025
A16: Grafana | B16: Ambiente de monitoramento dos dados | C16: Thi | D16: Done | E16: H1'2025
A17: Integração | B17: Desenvolver API People | C17: Icaro | D17: Done | E17: H1'2025
A18: Posições | B18: Correção dos Workflows com posição obrigatória | C18: Ca | D18: Done | E18: H2'2025
... A20: Novas datas movimentação | B20: Alteração de cargo mensal | C20: Ca | D20: Done | E20: H2'2025
A21: Integração | B21: Integração Lever <> LG | C21: Icaro | D21: Doing | E21: 45962
A22: HRBP | B22: Onboarding Acessos + treinamento | C22: Kell | D22: TO DO | E22: 45992
A23: HRBP | B23: Acesso ao quadro de vaga | C23: Kell | D23: TO DO | E23: 45992
A24: Liderança | B24: Movimentações/Alterações | C24: Kell | D24: TO DO | E24: 45992
A25: Solicitações travadas por outras pendências | B25: Visibilidade de gaps ou reprovas | C25: Kell | D25: TO DO | E25: 45992
A26: Comunicação das etapas do fluxo: e-mail ou Slack | B26: Entender integração LG - Slack | C26: Kell | D26: TO DO | E26: 2026
A27: Data Lake | B27: API Afastamentos | C27: - | D27: TO DO | E27: 2026
A28: Data Lake | B28: API Avaliação | C28: - | D28: TO DO | E28: 2026
A29: Data Lake | B29: Dados históricos Pin People | C29: - | D29: TO DO | E29: 2026
A30: Data Lake | B30: API Férias LG | C30: - | D30: TO DO | E30: 2026
A31: Data Lake | B31: API Allocation | C31: - | D31: TO DO | E31: 2026
A32: Data Lake | B32: API Banco de Horas | C32: - | D32: TO DO | E32: 2026
... A50: Data Lake | B50: 99 hist | C50: - | D50: TO DO | E50: 2026

Sheet Painel Weekly
B1: Fev | F1: Mar
B2: S1 | C2: S2 | D2: S3 | E2: S4 | F2: S1 | G2: S2 | H2: S3 | I2: S2
A3: Carina Jorge Pinha | B3: =COUNTIFS(Weekly!$C:$C, $A3, Weekly!AB:AB, "x") -> 9 | C3: =COUNTIFS(Weekly!$C:$C, $A3, Weekly!AC:AC, "x") -> 6 | D3: =COUNTIFS(Weekly!$C:$C, $A3, Weekly!AD:AD, "x") -> 6 | E3: =COUNTIFS(Weekly!$C:$C, $A3, Weekly!AE:AE, "x") -> 8 | F3: =COUNTIFS(Weekly!$C:$C, $A3, Weekly!AF:AF, "x") -> 9 | G3: =COUNTIFS(Weekly!$C:$C, $A3, Weekly!AG:AG, "x") -> 9 | H3: =COUNTIFS(Weekly!$C:$C, $A3, Weekly!AH:AH, "x") -> 10 | I3: =COUNTIFS(Weekly!$C:$C, $A3, Weekly!AN:AN, "x") -> #VALUE!
A4: Andreza Cardoso Pimenta | B4: =COUNTIFS(Weekly!$C:$C, $A4, Weekly!AB:AB, "x") -> 13 | C4: =COUNTIFS(Weekly!$C:$C, $A4, Weekly!AC:AC, "x") -> 14 | D4: =COUNTIFS(Weekly!$C:$C, $A4, Weekly!AD:AD, "x") -> 10 | E4: =COUNTIFS(Weekly!$C:$C, $A4, Weekly!AE:AE, "x") -> 11 | F4: =COUNTIFS(Weekly!$C:$C, $A4, Weekly!AF:AF, "x") -> 11 | G4: =COUNTIFS(Weekly!$C:$C, $A4, Weekly!AG:AG, "x") -> 9 | H4: =COUNTIFS(Weekly!$C:$C, $A4, Weekly!AH:AH, "x") -> 9 | I4: =COUNTIFS(Weekly!$C:$C, $A4, Weekly!AN:AN, "x") -> #VALUE!
A5: Thiago Lopes Pereira | B5: =COUNTIFS(Weekly!$C:$C, $A5, Weekly!AB:AB, "x") -> 8 | C5: =COUNTIFS(Weekly!$C:$C, $A5, Weekly!AC:AC, "x") -> 8 | D5: =COUNTIFS(Weekly!$C:$C, $A5, Weekly!AD:AD, "x") -> 8 | E5: =COUNTIFS(Weekly!$C:$C, $A5, Weekly!AE:AE, "x") -> 5 | F5: =COUNTIFS(Weekly!$C:$C, $A5, Weekly!AF:AF, "x") -> 5 | G5: =COUNTIFS(Weekly!$C:$C, $A5, Weekly!AG:AG, "x") -> 4 | H5: =COUNTIFS(Weekly!$C:$C, $A5, Weekly!AH:AH, "x") -> 4 | I5: =COUNTIFS(Weekly!$C:$C, $A5, Weekly!AN:AN, "x") -> #VALUE!
A6: Stephanie Da Costa Calandrine | B6: =COUNTIFS(Weekly!$C:$C, $A6, Weekly!AB:AB, "x") -> 6 | C6: =COUNTIFS(Weekly!$C:$C, $A6, Weekly!AC:AC, "x") -> 11 | D6: =COUNTIFS(Weekly!$C:$C, $A6, Weekly!AD:AD, "x") -> 11 | E6: =COUNTIFS(Weekly!$C:$C, $A6, Weekly!AE:AE, "x") -> 8 | F6: =COUNTIFS(Weekly!$C:$C, $A6, Weekly!AF:AF, "x") -> 9 | G6: =COUNTIFS(Weekly!$C:$C, $A6, Weekly!AG:AG, "x") -> 8 | H6: =COUNTIFS(Weekly!$C:$C, $A6, Weekly!AH:AH, "x") -> 9 | I6: =COUNTIFS(Weekly!$C:$C, $A6, Weekly!AN:AN, "x") -> #VALUE!
A7: Sabrina Mendes | B7: =COUNTIFS(Weekly!$C:$C, $A7, Weekly!AB:AB, "x") -> 3 | C7: =COUNTIFS(Weekly!$C:$C, $A7, Weekly!AC:AC, "x") -> 6 | D7: =COUNTIFS(Weekly!$C:$C, $A7, Weekly!AD:AD, "x") -> 6 | E7: =COUNTIFS(Weekly!$C:$C, $A7, Weekly!AE:AE, "x") -> 2 | F7: =COUNTIFS(Weekly!$C:$C, $A7, Weekly!AF:AF, "x") -> 5 | G7: =COUNTIFS(Weekly!$C:$C, $A7, Weekly!AG:AG, "x") -> 4 | H7: =COUNTIFS(Weekly!$C:$C, $A7, Weekly!AH:AH, "x") -> 4 | I7: =COUNTIFS(Weekly!$C:$C, $A7, Weekly!AN:AN, "x") -> #VALUE!
A8: Icaro Ribeiro | B8: =COUNTIFS(Weekly!$C:$C, $A8, Weekly!AB:AB, "x") -> 1 | C8: =COUNTIFS(Weekly!$C:$C, $A8, Weekly!AC:AC, "x") -> 1 | D8: =COUNTIFS(Weekly!$C:$C, $A8, Weekly!AD:AD, "x") -> 1 | E8: =COUNTIFS(Weekly!$C:$C, $A8, Weekly!AE:AE, "x") -> 1 | F8: =COUNTIFS(Weekly!$C:$C, $A8, Weekly!AF:AF, "x") -> 0 | G8: =COUNTIFS(Weekly!$C:$C, $A8, Weekly!AG:AG, "x") -> 0 | H8: =COUNTIFS(Weekly!$C:$C, $A8, Weekly!AH:AH, "x") -> 0 | I8: =COUNTIFS(Weekly!$C:$C, $A8, Weekly!AN:AN, "x") -> #VALUE!
A9: Total | B9: =SUM(B3:B7) -> 39 | C9: =SUM(C3:C7) -> 45 | D9: =SUM(D3:D7) -> 41 | E9: =SUM(E3:E7) -> 34 | F9: =SUM(F3:F7) -> 39 | G9: =SUM(G3:G7) -> 34 | H9: =SUM(H3:H7) -> 36 | I9: =SUM(I3:I7) -> #VALUE!

Sheet Roadmap 2026
A1: Status | B1: Pilares da Estratégia | C1: Pilares | D1: Prioridade | E1: Iniciativa | F1: Owner | G1: Co Owner | H1: Trimestre | I1: ROI X Esforço
A2: Concluído | B2: Processes & Analytics | C2: Automação | D2: 1. Alta | E2: Mapeamento Automações People + HUB de Automação(N8N & Code) + IPA (Indice de Projetos Automatizados) | F2: Andreza | H2: Q1'26
A3: Em andamento | B3: Processes & Analytics | C3: Foundation | D3: 1. Alta | E3: Implantação TeamGuide: Pesquisa, LMS, Carreira e Skills + Engenharia: LG <>TeamGuide <> Data lake | F3: Andreza | G3: Thiago | H3: Q1'26
A4: Em andamento | B4: Processes & Analytics | C4: Data | D4: 1. Alta | E4: Maturidade: PA: Estruturação Modelo Consultoria ( Governança do Modelo) + TH (Implantar estratégia da Arquitetura com foco no preditivo e autonomia da liderança) | F4: Andreza | H4: Q3'26
A5: Em andamento | B5: Strong core | C5: BAU | D5: 3. Baixa | E5: Orçamento: Implantação Governança e Renovação de Sistemas (Linkedin, Pris, Teamguide etc) | F5: Andreza | H5: Q1'26
A6: Concluído | B6: Processes & Analytics | C6: Automação | D6: 1. Alta | E6: People Platform: Segmentação Usuário (Acessos plataformas/produtos PATH) + Leader Compass | F6: Carina | G6: Escobar | H6: Q2'26
A7: Em andamento | B7: Processes & Analytics | C7: Automação | D7: 1. Alta | E7: People Platform: Hiring: simplified journey + (Go Live Admissão + Alertas flow Slack) | F7: Carina | G7: Escobar | H7: Q2'26
A8: Em andamento | B8: Processes & Analytics | C8: Automação | D8: 1. Alta | E8: People Platform: Self-service changes on salary and allocation movimentation | F8: Carina | G8: Escobar | H8: Q2'26
A9: A iniciar | B9: Processes & Analytics | C9: Automação | D9: 1. Alta | E9: People Platform: simulations on payroll and HC | F9: Carina | G9: Escobar | H9: Q2'26
A10: A iniciar | B10: Processes & Analytics | C10: Foundation | D10: 3. Baixa | E10: Engenharia LG: ( Dados de Férias e Banco de horas) | F10: Icaro | H10: Q1'26
A11: A iniciar | B11: Processes & Analytics | C11: Foundation | D11: 2.Média | E11: Engenharia Lever: (Dados de Offers, oportunidades e Candidatos) | F11: Icaro | H11: Q2'26
A12: Em andamento | B12: Processes & Analytics | C12: Automação | D12: 2.Média | E12: Portifólio API People: Dados Sensíveis | F12: Icaro | H12: Q3'26
A13: Em andamento | B13: Processes & Analytics | C13: Data | D13: 2.Média | E13: Evolução BI: DDL(Lançamento + Capacitação Liderança) & XD com dados de remuneração,movimentações,TA (automação diária) | F13: Sabrina | G13: Stephanie | H13: Q1'26
A14: Em andamento | B14: Processes & Analytics | C14: BAU | D14: 3. Baixa | E14: DataViz: Revisão & Sustentação painéis legado | F14: Sabrina | H14: Q1'26
A15: A iniciar | B15: Processes & Analytics | C15: Data | D15: 2.Média | E15: TeamGuide: Dashboards (Liderança & HRBP's) + Sistematização GT 2026 | F15: Sabrina | H15: Q2'26
A16: A iniciar | B16: Processes & Analytics | C16: Data | D16: 3. Baixa | E16: Data: Turnover Preditivo | F16: Sabrina | H16: Q1'26
A17: Em andamento | B17: Processes & Analytics | C17: BAU | D17: 1. Alta | E17: Governança KPI: Definição + Gestão | F17: Stephanie | H17: Q1'26
A18: Concluído | B18: Strong core | C18: BAU | D18: 1. Alta | E18: Gestão de talentos 2025 | F18: Stephanie | G18: Thiago | H18: Q1'26
A19: Concluído | B19: Talent to value | C19: Data | D19: 1. Alta | E19: Modelo de trabalho: Conexão Neon e estudo Disponibilidade (Foundation Engenharia) | F19: Stephanie | G19: Icaro | H19: Q2'26
A20: Em andamento | B20: Talent to value | C20: Data | D20: 1. Alta | E20: Modelo de trabalho: Conexão Neon e Produtividade | F20: Stephanie | G20: Icaro | H20: Q2'26
A21: A iniciar | B21: Talent to value | C21: Data | D21: 1. Alta | E21: Design Organizacional com enfânse em People Allocation | F21: Stephanie | H21: Q3'26
A22: Em andamento | B22: Processes & Analytics | C22: Data | D22: 2.Média | E22: Estratégia de contratação | F22: Stephanie | H22: Q1'26
A23: A iniciar | B23: Plant the seeds | C23: Automação | D23: 2.Média | E23: Evolução Assistente IA: (Volumentria de dados e alertas líder) | F23: Thiago | G23: Carina | H23: Q1'26
A24: A iniciar | B24: Processes & Analytics | C24: Foundation | D24: 3. Baixa | E24: DataScience: DataMesh | F24: Thiago | H24: Q4'26
A25: Em andamento | B25: Processes & Analytics | C25: BAU | D25: 3. Baixa | E25: Sustentação Automação (Data Lake, API's etc, integrações) | F25: Thiago | H25: Q4'26

Sheet Cronogramas
A1: Timeline: Projetos
A2: Projeto | B2: Data Ini | C2: Data Fim | D2: Status | E2: Frente | F2: Entregável | G2: Owner | H2: CO Owner | I2: OBS
A3: TeamGuide | B3: 46104 | C3: =B3+4 -> 46108 | D3: Done | E3: Contrato | F3: Revisão contrato | G3: Rafael Nunes da Silva Baraccat | H3: Thiago Lopes Pereira
A4: TeamGuide | B4: 46111 | C4: =B4+11 -> 46122 | D4: Done | E4: Contrato | F4: Assintatura contrato | G4: Rafael Nunes da Silva Baraccat | H4: Thiago Lopes Pereira
A5: TeamGuide | B5: 46111 | C5: =B5+11 -> 46122 | D5: Done | E5: Contrato | F5: Abrir RC | G5: Rafael Nunes da Silva Baraccat | H5: Thiago Lopes Pereira
A6: TeamGuide | B6: 46146 | C6: =B6+11 -> 46157 | D6: Doing | E6: Backend | F6: Integração LG | G6: Andreza Cardoso Pimenta | H6: Thiago Lopes Pereira
A7: TeamGuide | B7: 46146 | C7: =B7+4 -> 46150 | D7: Done | E7: Backend | F7: Integração SSO | G7: Andreza Cardoso Pimenta | H7: Thiago Lopes Pereira | I7: Henrique Neves dos Reis será nosso suporte.
A8: TeamGuide | B8: 46146 | C8: =B8+11 -> 46157 | D8: To Do | E8: UX | F8: Customização Ambiente | G8: Keyse Terzi
A9: TeamGuide | B9: 46146 | C9: =B9+4 -> 46150 | D9: Done | E9: Pesquisa | F9: Treinamentos Steakholders implantação | G9: Rafael Nunes da Silva Baraccat
A10: TeamGuide | B10: 46146 | C10: =B10+11 -> 46157 | D10: Doing | E10: Pesquisa | F10: Onboarding: Revisão Questionário + Histórico de dados | G10: Julia Longo de Faria
A11: TeamGuide | B11: 46146 | C11: =B11+11 -> 46157 | D11: Doing | E11: Pesquisa | F11: Clima: Revisão Questionário + Histórico de dados | G11: Julia Longo de Faria
A12: TeamGuide | B12: 46146 | C12: =B12+11 -> 46157 | D12: Doing | E12: LMS | F12: Treinamento Obrigatório: Revisão Treinamentos + Histórico de dados | G12: Julia Longo de Faria
A13: TeamGuide | B13: 46146 | C13: =B13+11 -> 46157 | D13: Doing | E13: Pesquisa | F13: Demais Treinamentos: Revisão Treinamentos + Histórico de dados | G13: Julia Longo de Faria
A14: TeamGuide | B14: 46146 | C14: =B14+11 -> 46157 | D14: Doing | E14: Pesquisa | F14: Hiring Manager: Revisão Questionário + Histórico de dados | G14: Fernanda Nobre Granjo Lelli Almeida
A15: TeamGuide | B15: 46146 | C15: =B15+11 -> 46157 | D15: To Do | E15: Pesquisa | F15: Revisão Histórico de dados | G15: Rafael Nunes da Silva Baraccat
A16: TeamGuide | B16: 46146 | C16: =B16+11 -> 46157 | D16: To Do | E16: Data | F16: Sanite check data hierarquia | G16: Rafael Nunes da Silva Baraccat | H16: Thiago Lopes Pereira
A17: TeamGuide | B17: 46153 | C17: =B17+14 -> 46167 | D17: To Do | E17: Data | F17: Painel: Pesquisa de Onboarding | G17: Julia Longo de Faria | H17: Sabrina Mendes
A18: TeamGuide | B18: 46153 | C18: =B18+14 -> 46167 | D18: To Do | E18: Data | F18: Painel: Pesquisa Hiring Manager | G18: Fernanda Nobre Granjo Lelli Almeida | H18: Sabrina Mendes
A19: TeamGuide | B19: 46153 | C19: =B19+14 -> 46167 | D19: To Do | E19: Data | F19: Painel: Treinamentos | G19: Julia Longo de Faria | H19: Sabrina Mendes
A20: TeamGuide | B20: 46153 | C20: =B20+14 -> 46167 | D20: To Do | E20: Data | F20: Painel: Pesquisa de Clima | G20: Julia Longo de Faria | H20: Sabrina Mendes
A21: TeamGuide | B21: 46153 | C21: =B21+4 -> 46157 | D21: To Do | E21: UX | F21: Revisão textos | G21: Keyse Terzi
A22: TeamGuide | B22: 46153 | C22: =B22+4 -> 46157 | D22: To Do | E22: Pesquisa | F22: Onboarding: Implementação Questionário | G22: Julia Longo de Faria | H22: Sabrina Mendes
A23: TeamGuide | B23: 46153 | C23: =B23+4 -> 46157 | D23: To Do | E23: Pesquisa | F23: Clima: Implementação Questionário | G23: Julia Longo de Faria | H23: Sabrina Mendes
A24: TeamGuide | B24: 46153 | C24: =B24+4 -> 46157 | D24: To Do | E24: LMS | F24: Clima: Implementação Treinamentos | G24: Julia Longo de Faria | H24: Sabrina Mendes
A25: TeamGuide | B25: 46153 | C25: =B25+4 -> 46157 | D25: To Do | E25: Pesquisa | F25: Hiring manager: Implementação Questionário | G25: Julia Longo de Faria | H25: Sabrina Mendes
A26: TeamGuide | B26: 46153 | C26: =B26+4 -> 46157 | D26: To Do | E26: LMS | F26: Parametrização Treinamentos | G26: Julia Longo de Faria
A27: TeamGuide | B27: 46153 | C27: =B27+4 -> 46157 | D27: To Do | E27: LMS | F27: Parametrização Pesquisas | G27: Rafael Nunes da Silva Baraccat
A28: TeamGuide | B28: 46160 | C28: =B28+3 -> 46163 | D28: To Do | E28: Pesquisa | F28: Parametrização Envios + MVP | G28: Rafael Nunes da Silva Baraccat
A29: TeamGuide | B29: 46160 | C29: =B29+3 -> 46163 | D29: To Do | E29: LMS | F29: Gestão de Acessos | G29: Rafael Nunes da Silva Baraccat
A30: TeamGuide | B30: 46160 | C30: =B30+3 -> 46163 | D30: To Do | E30: Pesquisa | F30: Gestão de Acessos | G30: Rafael Nunes da Silva Baraccat
A31: TeamGuide | B31: 46167 | C31: =B31+11 -> 46178 | D31: To Do | E31: LMS | F31: MVP People + Amostragem | G31: Rafael Nunes da Silva Baraccat
A32: TeamGuide | B32: 46174 | C32: =B32+29 -> 46203 | D32: To Do | E32: Data | F32: Painel Gestão de Talentos | G32: Gabriela Gonçales | H32: Rafael Nunes da Silva Baraccat
A33: TeamGuide | B33: 46174 | C33: =B33+15 -> 46189 | D33: To Do | E33: GT | F33: Implantação: Pesquisas GT | G33: Gabriela Gonçales | H33: Rafael Nunes da Silva Baraccat
A34: TeamGuide | B34: 46174 | C34: =B34+15 -> 46189 | D34: To Do | E34: GT | F34: Implantação: 1:1 e PDI | G34: Gabriela Gonçales | H34: Rafael Nunes da Silva Baraccat
A35: TeamGuide | B35: 46174 | C35: =B35+15 -> 46189 | D35: To Do | E35: Engineering | F35: Data Lake: Dados de Pesquisa | G35: Thiago Lopes Pereira
A36: TeamGuide | B36: 46174 | C36: =B36+29 -> 46203 | D36: To Do | E36: Skills | F36: Painel Skills | G36: Gabriela Gonçales | H36: Rafael Nunes da Silva Baraccat
A37: TeamGuide | B37: 46174 | C37: =B37+15 -> 46189 | D37: To Do | E37: Skills | F37: Implantação: Módulo de Skills | G37: Gabriela Gonçales | H37: Rafael Nunes da Silva Baraccat
A38: TeamGuide | B38: 46189 | C38: =B38+15 -> 46204 | D38: To Do | E38: Engineering | F38: Data Lake: Dados de Treinamento | G38: Thiago Lopes Pereira
A39: TeamGuide | B39: 46190 | C39: =B39+15 -> 46205 | D39: To Do | E39: GT | F39: Implantação: Dados históricos módulo | G39: Gabriela Gonçales | H39: Rafael Nunes da Silva Baraccat
A40: TeamGuide | B40: 46205 | C40: =B40+15 -> 46220 | D40: To Do | E40: Engineering | F40: Data Lake: Dados de Avaliação | G40: Thiago Lopes Pereira
...

Sheet Cronograma Projetos

Sheet Férias
C1: Férias ou Conexão Neon
C2: Ativo
C4: Mai | E4: Jun | I4: Cont | J4: Jul | N4: Ago | R4: Set | V4: Out
B5: PATH | C5: S3 | D5: S4 | E5: S1 | F5: S2 | G5: S3 | H5: S4 | I5: - | J5: S1 | K5: S2 | L5: S3 | M5: S4 | N5: S1 | O5: S2 | P5: S3 | Q5: S4 | R5: S1 | S5: S2 | T5: S3 | U5: S4 | V5: S1 | W5: S2 | X5: S3 | Y5: S4
B6: Dias | C6: 5 | D6: 5 | E6: 3 | F6: 5 | G6: 5 | H6: 5 | I6: =SUM(C6:H6)/5 -> 5.6
B7: Komuta | C7: CN | D7: 27 | E7: - | F7: 8 | I7: 5.3
B8: Andreza | C8: CN | E8: 46146 | F8: 8 | G8: 15 | I8: 4.3 | L8: 20 | M8: 3
B9: Carina | C9: CN | E9: 46146 | H9: 29 | I9: 5.3 | J9: - | K9: - | L9: - | M9: 28
B10: Step | C10: CN | E10: 46146 | I10: 6.3 | J10: 6 | K10: - | L10: 20
B11: Sa | C11: CN | E11: 46146 | I11: 6.3 | Q11: 24 | R11: 31 | X11: 19 | Y11: 30
B12: Thi | C12: CN | E12: 46146 | I12: 6.3 | L12: 20 | M12: - | N12: 7
B13: Rafa | C13: CN | E13: 46146 | G13: 22 | H13: - | I13: 4.3 | J13: 7

Sheet Painel Roadmap
A2: {=UNIQUE('Roadmap 2026'!B:B)} -> Pilares da Estratégia | B2: % | D2: Pilares | E2: % | G2: Prioridade | H2: %
A3: Processes & Analytics | B3: =COUNTIF('Roadmap 2026'!B:B,A3)/$B$18 -> 0.75 | D3: Automação | E3: =COUNTIF('Roadmap 2026'!C:C,D3)/$B$18 -> 0.29166667 | G3: 1. Alta | H3: =COUNTIF('Roadmap 2026'!D:D,G3)/$B$18 -> 0.5
A4: Strong core | B4: =COUNTIF('Roadmap 2026'!B:B,A4)/$B$18 -> 0.083333333 | D4: Data | E4: =COUNTIF('Roadmap 2026'!C:C,D4)/$B$18 -> 0.33333333 | G4: 2.Média | H4: =COUNTIF('Roadmap 2026'!D:D,G4)/$B$18 -> 0.25
A5: Talent to value | B5: =COUNTIF('Roadmap 2026'!B:B,A5)/$B$18 -> 0.125 | D5: Foundation | E5: =COUNTIF('Roadmap 2026'!C:C,D5)/$B$18 -> 0.16666667 | G5: 3. Baixa | H5: =COUNTIF('Roadmap 2026'!D:D,G5)/$B$18 -> 0.25
A6: Plant the seeds | B6: =COUNTIF('Roadmap 2026'!B:B,A6)/$B$18 -> 0.041666667 | D6: BAU | E6: =COUNTIF('Roadmap 2026'!C:C,D6)/$B$18 -> 0.20833333
B9: Owner | D9: Co Owner | E9: Total
A10: Andreza | B10: =COUNTIF('Roadmap 2026'!F:F,$A10) -> 4 | D10: =COUNTIF('Roadmap 2026'!G:G,$A10) -> 0 | E10: =SUM(B10:D10) -> 4
A11: Stephanie | B11: =COUNTIF('Roadmap 2026'!F:F,$A11) -> 6 | D11: =COUNTIF('Roadmap 2026'!G:G,$A11) -> 1 | E11: =SUM(B11:D11) -> 7
A12: Carina | B12: =COUNTIF('Roadmap 2026'!F:F,$A12) -> 4 | D12: =COUNTIF('Roadmap 2026'!G:G,$A12) -> 1 | E12: =SUM(B12:D12) -> 5
A13: Sabrina | B13: =COUNTIF('Roadmap 2026'!F:F,$A13) -> 4 | D13: =COUNTIF('Roadmap 2026'!G:G,$A13) -> 0 | E13: =SUM(B13:D13) -> 4
A14: Thiago | B14: =COUNTIF('Roadmap 2026'!F:F,$A14) -> 3 | D14: =COUNTIF('Roadmap 2026'!G:G,$A14) -> 2 | E14: =SUM(B14:D14) -> 5
A15: Icaro | B15: =COUNTIF('Roadmap 2026'!F:F,$A15) -> 3 | D15: =COUNTIF('Roadmap 2026'!G:G,$A15) -> 2 | E15: =SUM(B15:D15) -> 5 | F15: PT
A16: Escobar | B16: =COUNTIF('Roadmap 2026'!F:F,$A16) -> 0 | D16: =COUNTIF('Roadmap 2026'!G:G,$A16) -> 4 | E16: =SUM(B16:D16) -> 4 | F16: PT
A17: Temporário Bre
B18: =SUM(B10:B17) -> 24 | C18: =SUM(C10:C16) -> 0 | D18: =SUM(D10:D16) -> 10 | E18: =SUM(E10:E16) -> 34

Sheet TeamGuide Crono
B2: Mar | J2: Abr | R2: Mai
B3: D | C3: S | D3: T | E3: Q | F3: Q | G3: S | H3: S | J3: D | K3: S | L3: T | M3: Q | N3: Q | O3: S | P3: S | R3: D | S3: S | T3: T | U3: Q | V3: Q | W3: S | X3: S
C4: 2 | D4: =C4+1 -> 3 | E4: =D4+1 -> 4 | F4: =E4+1 -> 5 | G4: =F4+1 -> 6 | H4: =G4+1 -> 7 | J4: 5 | K4: 6 | L4: =K4+1 -> 7 | M4: =L4+1 -> 8 | N4: =M4+1 -> 9 | O4: =N4+1 -> 10 | P4: =O4+1 -> 11 | R4: 3 | S4: =R4+1 -> 4 | T4: =S4+1 -> 5 | U4: =T4+1 -> 6 | V4: =U4+1 -> 7 | W4: =V4+1 -> 8 | X4: =W4+1 -> 9
B5: =H4+1 -> 8 | C5: =B5+1 -> 9 | D5: =C5+1 -> 10 | E5: =D5+1 -> 11 | F5: =E5+1 -> 12 | G5: =F5+1 -> 13 | H5: =G5+1 -> 14 | J5: =P4+1 -> 12 | K5: =J5+1 -> 13 | L5: =K5+1 -> 14 | M5: =L5+1 -> 15 | N5: =M5+1 -> 16 | O5: =N5+1 -> 17 | P5: =O5+1 -> 18 | R5: =X4+1 -> 10 | S5: =R5+1 -> 11 | T5: =S5+1 -> 12 | U5: =T5+1 -> 13 | V5: =U5+1 -> 14 | W5: =V5+1 -> 15 | X5: =W5+1 -> 16
B6: =H5+1 -> 15 | C6: =B6+1 -> 16 | D6: =C6+1 -> 17 | E6: =D6+1 -> 18 | F6: =E6+1 -> 19 | G6: =F6+1 -> 20 | H6: =G6+1 -> 21 | J6: =P5+1 -> 19 | K6: =J6+1 -> 20 | L6: =K6+1 -> 21 | M6: =L6+1 -> 22 | N6: =M6+1 -> 23 | O6: =N6+1 -> 24 | P6: =O6+1 -> 25 | R6: =X5+1 -> 17 | S6: =R6+1 -> 18 | T6: =S6+1 -> 19 | U6: =T6+1 -> 20 | V6: =U6+1 -> 21 | W6: =V6+1 -> 22 | X6: =W6+1 -> 23
B7: =H6+1 -> 22 | C7: =B7+1 -> 23 | D7: =C7+1 -> 24 | E7: =D7+1 -> 25 | F7: =E7+1 -> 26 | G7: =F7+1 -> 27 | H7: =G7+1 -> 28 | J7: =P6+1 -> 26 | K7: =J7+1 -> 27 | L7: =K7+1 -> 28 | M7: =L7+1 -> 29 | N7: =M7+1 -> 30 | O7: 1 | P7: 2 | R7: =X6+1 -> 24 | S7: =R7+1 -> 25 | T7: =S7+1 -> 26 | U7: =T7+1 -> 27 | V7: =U7+1 -> 28 | W7: =V7+1 -> 29 | X7: =W7+1 -> 30
B8: =H7+1 -> 29 | C8: =B8+1 -> 30 | D8: =C8+1 -> 31 | E8: 1 | F8: =E8+1 -> 2 | G8: =F8+1 -> 3 | H8: =G8+1 -> 4 | R8: =X7+1 -> 31
AA9: 46113 | AB9: 46120
M10: Contrato + Jurídico QR | Z10: LMS | AA10: Obrigatório | AB10: Demais treinamentos
B11: Jun | M11: Kick off | Z11: Pesquisa | AA11: onboarding | AB11: 7, 60 e 90
B12: D | C12: S | D12: T | E12: Q | F12: Q | G12: S | H12: S | M12: Aviso Distrato QR (60 dias antes) | AA12: hiring Manager | AB12: 7 e90
C13: 1 | D13: =C13+1 -> 2 | E13: =D13+1 -> 3 | F13: =E13+1 -> 4 | G13: =F13+1 -> 5 | H13: =G13+1 -> 6 | M13: Integração LG e SSO | AA13: clima | AB13: Trimestral
B14: =H13+1 -> 7 | C14: =B14+1 -> 8 | D14: =C14+1 -> 9 | E14: =D14+1 -> 10 | F14: =E14+1 -> 11 | G14: =F14+1 -> 12 | H14: =G14+1 -> 13 | M14: LMS e Pesquisa
B15: =H14+1 -> 14 | C15: =B15+1 -> 15 | D15: =C15+1 -> 16 | E15: =D15+1 -> 17 | F15: =E15+1 -> 18 | G15: =F15+1 -> 19 | H15: =G15+1 -> 20 | M15: Go Live
B16: =H15+1 -> 21 | C16: =B16+1 -> 22 | D16: =C16+1 -> 23 | E16: =D16+1 -> 24 | F16: =E16+1 -> 25 | G16: =F16+1 -> 26 | H16: =G16+1 -> 27 | M16: LMS e Pesquisa
B17: =H16+1 -> 28 | C17: =B17+1 -> 29 | D17: =C17+1 -> 30 | E17: 1 | F17: 2 | G17: 3 | M17: Lançamento Pesquisa
M18: Treinamento Obrigatório
M19: Gestão de Talentos
B25: Mar | J25: Abr | R25: Mai
B26: D | C26: S | D26: T | E26: Q | F26: Q | G26: S | H26: S | J26: D | K26: S | L26: T | M26: Q | N26: Q | O26: S | P26: S | R26: D | S26: S | T26: T | U26: Q | V26: Q | W26: S | X26: S
C27: 2 | D27: =C27+1 -> 3 | E27: =D27+1 -> 4 | F27: =E27+1 -> 5 | G27: =F27+1 -> 6 | H27: =G27+1 -> 7 | J27: 5 | K27: 6 | L27: =K27+1 -> 7 | M27: =L27+1 -> 8 | N27: =M27+1 -> 9 | O27: =N27+1 -> 10 | P27: =O27+1 -> 11 | R27: 3 | S27: =R27+1 -> 4 | T27: =S27+1 -> 5 | U27: =T27+1 -> 6 | V27: =U27+1 -> 7 | W27: =V27+1 -> 8 | X27: =W27+1 -> 9
B28: =H27+1 -> 8 | C28: =B28+1 -> 9 | D28: =C28+1 -> 10 | E28: =D28+1 -> 11 | F28: =E28+1 -> 12 | G28: =F28+1 -> 13 | H28: =G28+1 -> 14 | J28: =P27+1 -> 12 | K28: =J28+1 -> 13 | L28: =K28+1 -> 14 | M28: =L28+1 -> 15 | N28: =M28+1 -> 16 | O28: =N28+1 -> 17 | P28: =O28+1 -> 18 | R28: =X27+1 -> 10 | S28: =R28+1 -> 11 | T28: =S28+1 -> 12 | U28: =T28+1 -> 13 | V28: =U28+1 -> 14 | W28: =V28+1 -> 15 | X28: =W28+1 -> 16
B29: =H28+1 -> 15 | C29: =B29+1 -> 16 | D29: =C29+1 -> 17 | E29: =D29+1 -> 18 | F29: =E29+1 -> 19 | G29: =F29+1 -> 20 | H29: =G29+1 -> 21 | J29: =P28+1 -> 19 | K29: =J29+1 -> 20 | L29: =K29+1 -> 21 | M29: =L29+1 -> 22 | N29: =M29+1 -> 23 | O29: =N29+1 -> 24 | P29: =O29+1 -> 25 | R29: =X28+1 -> 17 | S29: =R29+1 -> 18 | T29: =S29+1 -> 19 | U29: =T29+1 -> 20 | V29: =U29+1 -> 21 | W29: =V29+1 -> 22 | X29: =W29+1 -> 23
B30: =H29+1 -> 22 | C30: =B30+1 -> 23 | D30: =C30+1 -> 24 | E30: =D30+1 -> 25 | F30: =E30+1 -> 26 | G30: =F30+1 -> 27 | H30: =G30+1 -> 28 | J30: =P29+1 -> 26 | K30: =J30+1 -> 27 | L30: =K30+1 -> 28 | M30: =L30+1 -> 29 | N30: =M30+1 -> 30 | O30: 1 | P30: 2 | R30: =X29+1 -> 24 | S30: =R30+1 -> 25 | T30: =S30+1 -> 26 | U30: =T30+1 -> 27 | V30: =U30+1 -> 28 | W30: =V30+1 -> 29 | X30: =W30+1 -> 30
B31: =H30+1 -> 29 | C31: =B31+1 -> 30 | D31: =C31+1 -> 31 | E31: 1 | F31: =E31+1 -> 2 | G31: =F31+1 -> 3 | H31: =G31+1 -> 4 | R31: =X30+1 -> 31
AA32: 46113 | AB32: 46120
M33: Contrato + Jurídico QR | Z33: LMS | AA33: Obrigatório | AB33: Demais treinamentos
B34: Jun | M34: Kick off | Z34: Pesquisa | AA34: onboarding | AB34: 7, 60 e 90
B35: D | C35: S | D35: T | E35: Q | F35: Q | G35: S | H35: S | M35: Aviso Distrato QR (60 dias antes) | AA35: hiring Manager | AB35: 7 e90
C36: 1 | D36: =C36+1 -> 2 | E36: =D36+1 -> 3 | F36: =E36+1 -> 4 | G36: =F36+1 -> 5 | H36: =G36+1 -> 6 | M36: Integração LG e SSO | AA36: clima | AB36: Trimestral
B37: =H36+1 -> 7 | C37: =B37+1 -> 8 | D37: =C37+1 -> 9 | E37: =D37+1 -> 10 | F37: =E37+1 -> 11 | G37: =F37+1 -> 12 | H37: =G37+1 -> 13 | M37: LMS e Pesquisa
B38: =H37+1 -> 14 | C38: =B38+1 -> 15 | D38: =C38+1 -> 16 | E38: =D38+1 -> 17 | F38: =E38+1 -> 18 | G38: =F38+1 -> 19 | H38: =G38+1 -> 20 | M38: Go Live
B39: =H38+1 -> 21 | C39: =B39+1 -> 22 | D39: =C39+1 -> 23 | E39: =D39+1 -> 24 | F39: =E39+1 -> 25 | G39: =F39+1 -> 26 | H39: =G39+1 -> 27 | M39: LMS e Pesquisa
B40: =H39+1 -> 28 | C40: =B40+1 -> 29 | D40: =C40+1 -> 30 | E40: 1 | F40: 2 | G40: 3 | M40: Lançamento Pesquisa
M41: Treinamento Obrigatório
M42: Gestão de Talentos

Sheet DataGOV
A1: Tema | B1: Campo | C1: Tipo | D1: Origem | E1: Tabela | F1: Reponsável | G1: Alimenta outro sistema? Quais? | H1: Alimenta quantos Sistemas? | I1: Dado Sensível? | J1: Atualização | K1: Erros Reportados | L1: Risco
A2: Cargo | B2: Level | C2: varchar | D2: LG | E2: API: Tabela Salarial | F2: TR | G2: SAP, SGN, Marauder, Jumpcloud, App Neon, Jira, PeopleAllocation e TeamGuide | H2: =IFERROR(__xludf.DUMMYFUNCTION("IF(ISBLANK(G2), 0, IF(TRIM(REGEXREPLACE(G2, ""(?i)\be\b|,"", """"))="""", 0, LEN(TRIM(REGEXREPLACE(G2, ""(?i)\be\b|,"", """"))) - LEN(SUBSTITUTE(TRIM(REGEXREPLACE(G2, ""(?i)\be\b|,"", """")), "" "", """")) + 1))"),9.0) -> 9 | J2: Mensal | K2: sim | L2: =IF(H2<0,0,H2*0.05)+ IF(K2="sim",0.15,0)+ IF(D2="Excel",0.1,0)+IF(I2="Sensível",0.1,0) -> 0.6
A3: Hierarquia | B3: Gestor | C3: varchar | D3: LG | E3: API: Tabela Hierarquia | F3: HRBPs | G3: SAP, Jira, Marauder, PeopleAllocation e TeamGuide | H3: =IFERROR(__xludf.DUMMYFUNCTION("IF(ISBLANK(G3), 0, IF(TRIM(REGEXREPLACE(G3, ""(?i)\be\b|,"", """"))="""", 0, LEN(TRIM(REGEXREPLACE(G3, ""(?i)\be\b|,"", """"))) - LEN(SUBSTITUTE(TRIM(REGEXREPLACE(G3, ""(?i)\be\b|,"", """")), "" "", """")) + 1))"),5.0) -> 5 | J3: Diário | K3: sim | L3: =IF(H3<0,0,H3*0.05)+ IF(K3="sim",0.15,0)+ IF(D3="Excel",0.1,0)+IF(I3="Sensível",0.1,0) -> 0.4
A4: Cadastro | B4: Empresa | C4: varchar | D4: LG | E4: API: Tabela Colaborador | F4: POPs | G4: ServiceNow, Marauder e TeamGuide | H4: =IFERROR(__xludf.DUMMYFUNCTION("IF(ISBLANK(G4), 0, IF(TRIM(REGEXREPLACE(G4, ""(?i)\be\b|,"", """"))="""", 0, LEN(TRIM(REGEXREPLACE(G4, ""(?i)\be\b|,"", """"))) - LEN(SUBSTITUTE(TRIM(REGEXREPLACE(G4, ""(?i)\be\b|,"", """")), "" "", """")) + 1))"),3.0) -> 3 | I4: Sensível | J4: Pontualmente | K4: sim | L4: =IF(H4<0,0,H4*0.05)+ IF(K4="sim",0.15,0)+ IF(D4="Excel",0.1,0)+IF(I4="Sensível",0.1,0) -> 0.4
A5: Cadastro | B5: cpf_cod | C5: varchar | D5: LG | E5: API: Tabela Colaborador | F5: POPs | G5: KYC, SGN, Jira e N8N | H5: =IFERROR(__xludf.DUMMYFUNCTION("IF(ISBLANK(G5), 0, IF(TRIM(REGEXREPLACE(G5, ""(?i)\be\b|,"", """"))="""", 0, LEN(TRIM(REGEXREPLACE(G5, ""(?i)\be\b|,"", """"))) - LEN(SUBSTITUTE(TRIM(REGEXREPLACE(G5, ""(?i)\be\b|,"", """")), "" "", """")) + 1))"),4.0) -> 4 | I5: Sensível | J5: Na admissão | L5: =IF(H5<0,0,H5*0.05)+ IF(K5="sim",0.15,0)+ IF(D5="Excel",0.1,0)+IF(I5="Sensível",0.1,0) -> 0.3
A6: Cargo | B6: Especialidade | C6: varchar | D6: LG | E6: API: Tabela Salarial | F6: TR | G6: PeopleAllocation, DashbordlIA e TeamGuide | H6: =IFERROR(__xludf.DUMMYFUNCTION("IF(ISBLANK(G6), 0, IF(TRIM(REGEXREPLACE(G6, ""(?i)\be\b|,"", """"))="""", 0, LEN(TRIM(REGEXREPLACE(G6, ""(?i)\be\b|,"", """"))) - LEN(SUBSTITUTE(TRIM(REGEXREPLACE(G6, ""(?i)\be\b|,"", """")), "" "", """")) + 1))"),3.0) -> 3 | J6: Mensal | K6: sim | L6: =IF(H6<0,0,H6*0.05)+ IF(K6="sim",0.15,0)+ IF(D6="Excel",0.1,0)+IF(I6="Sensível",0.1,0) -> 0.3
A7: HIerarquia | B7: UO_ID | C7: varchar | D7: LG | E7: API: Tabela Hierarquia | F7: HRBPs | G7: People Allocation e TeamGuide | H7: =IFERROR(__xludf.DUMMYFUNCTION("IF(ISBLANK(G7), 0, IF(TRIM(REGEXREPLACE(G7, ""(?i)\be\b|,"", """"))="""", 0, LEN(TRIM(REGEXREPLACE(G7, ""(?i)\be\b|,"", """"))) - LEN(SUBSTITUTE(TRIM(REGEXREPLACE(G7, ""(?i)\be\b|,"", """")), "" "", """")) + 1))"),3.0) -> 3 | J7: Diário | K7: sim | L7: =IF(H7<0,0,H7*0.05)+ IF(K7="sim",0.15,0)+ IF(D7="Excel",0.1,0)+IF(I7="Sensível",0.1,0) -> 0.3
A8: Hierarquia | B8: Nome_N0 | C8: varchar | D8: LG | E8: API: Tabela Hierarquia | F8: HRBPs | G8: SAP, PeopleAllocation e TeamGuide | H8: =IFERROR(__xludf.DUMMYFUNCTION("IF(ISBLANK(G8), 0, IF(TRIM(REGEXREPLACE(G8, ""(?i)\be\b|,"", """"))="""", 0, LEN(TRIM(REGEXREPLACE(G8, ""(?i)\be\b|,"", """"))) - LEN(SUBSTITUTE(TRIM(REGEXREPLACE(G8, ""(?i)\be\b|,"", """")), "" "", """")) + 1))"),3.0) -> 3 | J8: Diário | K8: sim | L8: =IF(H8<0,0,H8*0.05)+ IF(K8="sim",0.15,0)+ IF(D8="Excel",0.1,0)+IF(I8="Sensível",0.1,0) -> 0.3
A9: Hierarquia | B9: Nome_N1 | C9: varchar | D9: LG | E9: API: Tabela Hierarquia | F9: HRBPs | G9: SAP, PeopleAllocation e TeamGuide | H9: =IFERROR(__xludf.DUMMYFUNCTION("IF(ISBLANK(G9), 0, IF(TRIM(REGEXREPLACE(G9, ""(?i)\be\b|,"", """"))="""", 0, LEN(TRIM(REGEXREPLACE(G9, ""(?i)\be\b|,"", """"))) - LEN(SUBSTITUTE(TRIM(REGEXREPLACE(G9, ""(?i)\be\b|,"", """")), "" "", """")) + 1))"),3.0) -> 3 | J9: Diário | K9: sim | L9: =IF(H9<0,0,H9*0.05)+ IF(K9="sim",0.15,0)+ IF(D9="Excel",0.1,0)+IF(I9="Sensível",0.1,0) -> 0.3
A10: Hierarquia | B10: Nome_N2 a Nome_N7 | C10: varchar | D10: LG | E10: API: Tabela Hierarquia | F10: HRBPs | G10: SAP, PeopleAllocation e TeamGuide | H10: =IFERROR(__xludf.DUMMYFUNCTION("IF(ISBLANK(G10), 0, IF(TRIM(REGEXREPLACE(G10, ""(?i)\be\b|,"", """"))="""", 0, LEN(TRIM(REGEXREPLACE(G10, ""(?i)\be\b|,"", """"))) - LEN(SUBSTITUTE(TRIM(REGEXREPLACE(G10, ""(?i)\be\b|,"", """")), "" "", """")) + 1))"),3.0) -> 3 | J10: Diário | K10: sim | L10: =IF(H10<0,0,H10*0.05)+ IF(K10="sim",0.15,0)+ IF(D10="Excel",0.1,0)+IF(I10="Sensível",0.1,0) -> 0.3
A11: Hierarquia | B11: Centro de custo | C11: varchar | D11: LG | E11: API: Tabela Colaborador | F11: TR | G11: SAP e Marauder | H11: =IFERROR(__xludf.DUMMYFUNCTION("IF(ISBLANK(G11), 0, IF(TRIM(REGEXREPLACE(G11, ""(?i)\be\b|,"", """"))="""", 0, LEN(TRIM(REGEXREPLACE(G11, ""(?i)\be\b|,"", """"))) - LEN(SUBSTITUTE(TRIM(REGEXREPLACE(G11, ""(?i)\be\b|,"", """")), "" "", """")) + 1))"),2.0) -> 2 | J11: Diário | K11: sim | L11: =IF(H11<0,0,H11*0.05)+ IF(K11="sim",0.15,0)+ IF(D11="Excel",0.1,0)+IF(I11="Sensível",0.1,0) -> 0.25
A12: Cadastro | B12: E-mail | C12: varchar | D12: LG | E12: API: Tabela Colaborador | F12: POPs | G12: Marauder e TeamGuide | H12: =IFERROR(__xludf.DUMMYFUNCTION("IF(ISBLANK(G12), 0, IF(TRIM(REGEXREPLACE(G12, ""(?i)\be\b|,"", """"))="""", 0, LEN(TRIM(REGEXREPLACE(G12, ""(?i)\be\b|,"", """"))) - LEN(SUBSTITUTE(TRIM(REGEXREPLACE(G12, ""(?i)\be\b|,"", """")), "" "", """")) + 1))"),2.0) -> 2 | J12: Na admissão | K12: sim | L12: =IF(H12<0,0,H12*0.05)+ IF(K12="sim",0.15,0)+ IF(D12="Excel",0.1,0)+IF(I12="Sensível",0.1,0) -> 0.25
A13: Cadastro | B13: Data de Nascimento | C13: date | D13: LG | E13: API: Tabela Colaborador | F13: POPs | H13: =IFERROR(__xludf.DUMMYFUNCTION("IF(ISBLANK(G13), 0, IF(TRIM(REGEXREPLACE(G13, ""(?i)\be\b|,"", """"))="""", 0, LEN(TRIM(REGEXREPLACE(G13, ""(?i)\be\b|,"", """"))) - LEN(SUBSTITUTE(TRIM(REGEXREPLACE(G13, ""(?i)\be\b|,"", """")), "" "", """")) + 1))"),0.0) -> 0 | I13: Sensível | J13: Na admissão | K13: sim | L13: =IF(H13<0,0,H13*0.05)+ IF(K13="sim",0.15,0)+ IF(D13="Excel",0.1,0)+IF(I13="Sensível",0.1,0) -> 0.25
A14: Remuneração | B14: Target P4P (anual) | C14: float | D14: LG | E14: API: Tabela Salarial | F14: TR | H14: =IFERROR(__xludf.DUMMYFUNCTION("IF(ISBLANK(G14), 0, IF(TRIM(REGEXREPLACE(G14, ""(?i)\be\b|,"", """"))="""", 0, LEN(TRIM(REGEXREPLACE(G14, ""(?i)\be\b|,"", """"))) - LEN(SUBSTITUTE(TRIM(REGEXREPLACE(G14, ""(?i)\be\b|,"", """")), "" "", """")) + 1))"),0.0) -> 0 | I14: Sensível | J14: Diário | K14: sim | L14: =IF(H14<0,0,H14*0.05)+ IF(K14="sim",0.15,0)+ IF(D14="Excel",0.1,0)+IF(I14="Sensível",0.1,0) -> 0.25
A15: Hierarquia | B15: unid_org_n0_ds | C15: varchar | D15: LG | E15: API: Tabela Hierarquia | F15: HRBPs | G15: PeopleAllocation e TeamGuide | H15: =IFERROR(__xludf.DUMMYFUNCTION("IF(ISBLANK(G15), 0, IF(TRIM(REGEXREPLACE(G15, ""(?i)\be\b|,"", """"))="""", 0, LEN(TRIM(REGEXREPLACE(G15, ""(?i)\be\b|,"", """"))) - LEN(SUBSTITUTE(TRIM(REGEXREPLACE(G15, ""(?i)\be\b|,"", """")), "" "", """")) + 1))"),2.0) -> 2 | J15: Diário | K15: sim | L15: =IF(H15<0,0,H15*0.05)+ IF(K15="sim",0.15,0)+ IF(D15="Excel",0.1,0)+IF(I15="Sensível",0.1,0) -> 0.25
A16: Hierarquia | B16: unid_org_n1_ds | C16: varchar | D16: LG | E16: API: Tabela Hierarquia | F16: HRBPs | G16: PeopleAllocation e TeamGuide | H16: =IFERROR(__xludf.DUMMYFUNCTION("IF(ISBLANK(G16), 0, IF(TRIM(REGEXREPLACE(G16, ""(?i)\be\b|,"", """"))="""", 0, LEN(TRIM(REGEXREPLACE(G16, ""(?i)\be\b|,"", """"))) - LEN(SUBSTITUTE(TRIM(REGEXREPLACE(G16, ""(?i)\be\b|,"", """")), "" "", """")) + 1))"),2.0) -> 2 | J16: Diário | K16: sim | L16: =IF(H16<0,0,H16*0.05)+ IF(K16="sim",0.15,0)+ IF(D16="Excel",0.1,0)+IF(I16="Sensível",0.1,0) -> 0.25
A17: Hierarquia | B17: unid_org_n2_ds a unid_org_n7_ds | C17: varchar | D17: LG | E17: API: Tabela Hierarquia | F17: HRBPs | G17: PeopleAllocation e TeamGuide | H17: =IFERROR(__xludf.DUMMYFUNCTION("IF(ISBLANK(G17), 0, IF(TRIM(REGEXREPLACE(G17, ""(?i)\be\b|,"", """"))="""", 0, LEN(TRIM(REGEXREPLACE(G17, ""(?i)\be\b|,"", """"))) - LEN(SUBSTITUTE(TRIM(REGEXREPLACE(G17, ""(?i)\be\b|,"", """")), "" "", """")) + 1))"),2.0) -> 2 | J17: Diário | K17: sim | L17: =IF(H17<0,0,H17*0.05)+ IF(K17="sim",0.15,0)+ IF(D17="Excel",0.1,0)+IF(I17="Sensível",0.1,0) -> 0.25
A18: Avaliação | B18: Key Position | C18: varchar | D18: Excel | E18: Tabela Key Talents | F18: CT&D | G18: TeamGuide | H18: =IFERROR(__xludf.DUMMYFUNCTION("IF(ISBLANK(G18), 0, IF(TRIM(REGEXREPLACE(G18, ""(?i)\be\b|,"", """"))="""", 0, LEN(TRIM(REGEXREPLACE(G18, ""(?i)\be\b|,"", """"))) - LEN(SUBSTITUTE(TRIM(REGEXREPLACE(G18, ""(?i)\be\b|,"", """")), "" "", """")) + 1))"),1.0) -> 1 | I18: Sensível | J18: Semestral | L18: =IF(H18<0,0,H18*0.05)+ IF(K18="sim",0.15,0)+ IF(D18="Excel",0.1,0)+IF(I18="Sensível",0.1,0) -> 0.25
A19: Avaliação | B19: Key Talent | C19: varchar | D19: Excel | E19: Tabela Key Talents | F19: CT&D | G19: TeamGuide | H19: =IFERROR(__xludf.DUMMYFUNCTION("IF(ISBLANK(G19), 0, IF(TRIM(REGEXREPLACE(G19, ""(?i)\be\b|,"", """"))="""", 0, LEN(TRIM(REGEXREPLACE(G19, ""(?i)\be\b|,"", """"))) - LEN(SUBSTITUTE(TRIM(REGEXREPLACE(G19, ""(?i)\be\b|,"", """")), "" "", """")) + 1))"),1.0) -> 1 | I19: Sensível | J19: Semestral | L19: =IF(H19<0,0,H19*0.05)+ IF(K19="sim",0.15,0)+ IF(D19="Excel",0.1,0)+IF(I19="Sensível",0.1,0) -> 0.25
A20: Chave | B20: u00XX_id | C20: integer | D20: LG | E20: API: Tabela Colaborador | F20: Acessos | G20: Service Now, Marauder e AppNeon | H20: =IFERROR(__xludf.DUMMYFUNCTION("IF(ISBLANK(G20), 0, IF(TRIM(REGEXREPLACE(G20, ""(?i)\be\b|,"", """"))="""", 0, LEN(TRIM(REGEXREPLACE(G20, ""(?i)\be\b|,"", """"))) - LEN(SUBSTITUTE(TRIM(REGEXREPLACE(G20, ""(?i)\be\b|,"", """")), "" "", """")) + 1))"),4.0) -> 4 | J20: Na admissão | L20: =IF(H20<0,0,H20*0.05)+ IF(K20="sim",0.15,0)+ IF(D20="Excel",0.1,0)+IF(I20="Sensível",0.1,0) -> 0.2
A21: Hierarquia | B21: Unidade Organizacional | C21: varchar | D21: LG | E21: API: Tabela Hierarquia | F21: HRBPs | G21: TeamGuide | H21: =IFERROR(__xludf.DUMMYFUNCTION("IF(ISBLANK(G21), 0, IF(TRIM(REGEXREPLACE(G21, ""(?i)\be\b|,"", """"))="""", 0, LEN(TRIM(REGEXREPLACE(G21, ""(?i)\be\b|,"", """"))) - LEN(SUBSTITUTE(TRIM(REGEXREPLACE(G21, ""(?i)\be\b|,"", """")), "" "", """")) + 1))"),1.0) -> 1 | J21: Diário | K21: sim | L21: =IF(H21<0,0,H21*0.05)+ IF(K21="sim",0.15,0)+ IF(D21="Excel",0.1,0)+IF(I21="Sensível",0.1,0) -> 0.2
A22: ILP | B22: Socio | C22: varchar | D22: LG | E22: Tabela ILP | F22: TR | G22: TeamGuide | H22: =IFERROR(__xludf.DUMMYFUNCTION("IF(ISBLANK(G22), 0, IF(TRIM(REGEXREPLACE(G22, ""(?i)\be\b|,"", """"))="""", 0, LEN(TRIM(REGEXREPLACE(G22, ""(?i)\be\b|,"", """"))) - LEN(SUBSTITUTE(TRIM(REGEXREPLACE(G22, ""(?i)\be\b|,"", """")), "" "", """")) + 1))"),1.0) -> 1 | J22: Mensal | K22: sim | L22: =IF(H22<0,0,H22*0.05)+ IF(K22="sim",0.15,0)+ IF(D22="Excel",0.1,0)+IF(I22="Sensível",0.1,0) -> 0.2
A23: Cargo | B23: Agrupado Nível | C23: varchar | D23: Data Lake | E23: Lógica Calculada | F23: TR | G23: TeamGuide | H23: =IFERROR(__xludf.DUMMYFUNCTION("IF(ISBLANK(G23), 0, IF(TRIM(REGEXREPLACE(G23, ""(?i)\be\b|,"", """"))="""", 0, LEN(TRIM(REGEXREPLACE(G23, ""(?i)\be\b|,"", """"))) - LEN(SUBSTITUTE(TRIM(REGEXREPLACE(G23, ""(?i)\be\b|,"", """")), "" "", """")) + 1))"),1.0) -> 1 | J23: Mensal | K23: sim | L23: =IF(H23<0,0,H23*0.05)+ IF(K23="sim",0.15,0)+ IF(D23="Excel",0.1,0)+IF(I23="Sensível",0.1,0) -> 0.2
A24: Orçamento | B24: custo_base | C24: float | D24: Excel | E24: Tabela Orçamento | F24: TR | H24: =IFERROR(__xludf.DUMMYFUNCTION("IF(ISBLANK(G24), 0, IF(TRIM(REGEXREPLACE(G24, ""(?i)\be\b|,"", """"))="""", 0, LEN(TRIM(REGEXREPLACE(G24, ""(?i)\be\b|,"", """"))) - LEN(SUBSTITUTE(TRIM(REGEXREPLACE(G24, ""(?i)\be\b|,"", """")), "" "", """")) + 1))"),0.0) -> 0 | I24: Sensível | J24: Mensal | L24: =IF(H24<0,0,H24*0.05)+ IF(K24="sim",0.15,0)+ IF(D24="Excel",0.1,0)+IF(I24="Sensível",0.1,0) -> 0.2
A25: Orçamento | B25: custo_projetado_dez | C25: float | D25: Excel | E25: Tabela Orçamento | F25: TR | H25: =IFERROR(__xludf.DUMMYFUNCTION("IF(ISBLANK(G25), 0, IF(TRIM(REGEXREPLACE(G25, ""(?i)\be\b|,"", """"))="""", 0, LEN(TRIM(REGEXREPLACE(G25, ""(?i)\be\b|,"", """"))) - LEN(SUBSTITUTE(TRIM(REGEXREPLACE(G25, ""(?i)\be\b|,"", """")), "" "", """")) + 1))"),0.0) -> 0 | I25: Sensível | J25: Mensal | L25: =IF(H25<0,0,H25*0.05)+ IF(K25="sim",0.15,0)+ IF(D25="Excel",0.1,0)+IF(I25="Sensível",0.1,0) -> 0.2
A26: Remuneração | B26: Média Cargo | C26: float | D26: LG | E26: API: Tabela Salarial | F26: TR | G26: AppNeon | H26: =IFERROR(__xludf.DUMMYFUNCTION("IF(ISBLANK(G26), 0, IF(TRIM(REGEXREPLACE(G26, ""(?i)\be\b|,"", """"))="""", 0, LEN(TRIM(REGEXREPLACE(G26, ""(?i)\be\b|,"", """"))) - LEN(SUBSTITUTE(TRIM(REGEXREPLACE(G26, ""(?i)\be\b|,"", """")), "" "", """")) + 1))"),1.0) -> 1 | I26: Sensível | J26: Diário | L26: =IF(H26<0,0,H26*0.05)+ IF(K26="sim",0.15,0)+ IF(D26="Excel",0.1,0)+IF(I26="Sensível",0.1,0) -> 0.15
A27: Cluster | B27: Raça | C27: varchar | D27: LG | E27: API: Tabela Colaborador | F27: POPs | G27: TeamGuide | H27: =IFERROR(__xludf.DUMMYFUNCTION("IF(ISBLANK(G27), 0, IF(TRIM(REGEXREPLACE(G27, ""(?i)\be\b|,"", """"))="""", 0, LEN(TRIM(REGEXREPLACE(G27, ""(?i)\be\b|,"", """"))) - LEN(SUBSTITUTE(TRIM(REGEXREPLACE(G27, ""(?i)\be\b|,"", """")), "" "", """")) + 1))"),1.0) -> 1 | I27: Sensível | J27: Na admissão | L27: =IF(H27<0,0,H27*0.05)+ IF(K27="sim",0.15,0)+ IF(D27="Excel",0.1,0)+IF(I27="Sensível",0.1,0) -> 0.15
A28: Cargo | B28: Cargo | C28: varchar | D28: LG | E28: API: Tabela Colaborador | F28: HRBPs | H28: =IFERROR(__xludf.DUMMYFUNCTION("IF(ISBLANK(G28), 0, IF(TRIM(REGEXREPLACE(G28, ""(?i)\be\b|,"", """"))="""", 0, LEN(TRIM(REGEXREPLACE(G28, ""(?i)\be\b|,"", """"))) - LEN(SUBSTITUTE(TRIM(REGEXREPLACE(G28, ""(?i)\be\b|,"", """")), "" "", """")) + 1))"),0.0) -> 0 | J28: Mensal | K28: sim | L28: =IF(H28<0,0,H28*0.05)+ IF(K28="sim",0.15,0)+ IF(D28="Excel",0.1,0)+IF(I28="Sensível",0.1,0) -> 0.15
A29: Hierarquia | B29: Bu | C29: varchar | D29: Data Lake | E29: Lógica Calculada | F29: HRBPs | H29: =IFERROR(__xludf.DUMMYFUNCTION("IF(ISBLANK(G29), 0, IF(TRIM(REGEXREPLACE(G29, ""(?i)\be\b|,"", """"))="""", 0, LEN(TRIM(REGEXREPLACE(G29, ""(?i)\be\b|,"", """"))) - LEN(SUBSTITUTE(TRIM(REGEXREPLACE(G29, ""(?i)\be\b|,"", """")), "" "", """")) + 1))"),0.0) -> 0 | J29: Diário | K29: sim | L29: =IF(H29<0,0,H29*0.05)+ IF(K29="sim",0.15,0)+ IF(D29="Excel",0.1,0)+IF(I29="Sensível",0.1,0) -> 0.15
A30: Hierarquia | B30: BU/CoE/Plataform | C30: varchar | D30: Data Lake | E30: Lógica Calculada | F30: HRBPs | H30: =IFERROR(__xludf.DUMMYFUNCTION("IF(ISBLANK(G30), 0, IF(TRIM(REGEXREPLACE(G30, ""(?i)\be\b|,"", """"))="""", 0, LEN(TRIM(REGEXREPLACE(G30, ""(?i)\be\b|,"", """"))) - LEN(SUBSTITUTE(TRIM(REGEXREPLACE(G30, ""(?i)\be\b|,"", """")), "" "", """")) + 1))"),0.0) -> 0 | J30: Diário | K30: sim | L30: =IF(H30<0,0,H30*0.05)+ IF(K30="sim",0.15,0)+ IF(D30="Excel",0.1,0)+IF(I30="Sensível",0.1,0) -> 0.15
A31: Avaliação | B31: Conceito 2024.2 | C31: varchar | D31: TeamGuide | E31: Tabela QR | F31: CT&D | H31: =IFERROR(__xludf.DUMMYFUNCTION("IF(ISBLANK(G31), 0, IF(TRIM(REGEXREPLACE(G31, ""(?i)\be\b|,"", """"))="""", 0, LEN(TRIM(REGEXREPLACE(G31, ""(?i)\be\b|,"", """"))) - LEN(SUBSTITUTE(TRIM(REGEXREPLACE(G31, ""(?i)\be\b|,"", """")), "" "", """")) + 1))"),0.0) -> 0 | I31: Sensível | J31: Semestral | L31: =IF(H31<0,0,H31*0.05)+ IF(K31="sim",0.15,0)+ IF(D31="Excel",0.1,0)+IF(I31="Sensível",0.1,0) -> 0.1
